<?xml version="1.0" ?>
<!-- =================================================================================== -->
<!-- |    This document was autogenerated by xacro from rover1.urdf.xacro              | -->
<!-- |    EDITING THIS FILE BY HAND IS NOT RECOMMENDED                                 | -->
<!-- =================================================================================== -->
<robot name="paul">
  <material name="blue">
    <color rgba="0 0 0.8 1"/>
  </material>
  <material name="black">
    <color rgba="0 0 0 1"/>
  </material>
  <material name="green">
    <color rgba="0 1 0 1"/>
  </material>
  <material name="white">
    <color rgba="1 1 1 1"/>
  </material>
  <material name="orange">
    <color rgba="1.0 0.4235294117647059 0.0392156862745098 1.0"/>
  </material>
  <link name="base_link">
    <visual>
      <geometry>
        <box size="1 1 0.3"/>
      </geometry>
      <material name="blue"/>
    </visual>
    <collision>
      <geometry>
        <box size="1 1 0.3"/>
      </geometry>
    </collision>
    <inertial>
      <mass value="46"/>
      <inertia ixx="1.0" ixy="0.0" ixz="0.0" iyy="1.0" iyz="0.0" izz="1.0"/>
    </inertial>
  </link>
  <link name="right_rocker1">
    <visual>
      <geometry>
        <box size="0.5982900000000001 0.05 0.05"/>
      </geometry>
      <origin rpy="0  0.78539816339 0" xyz="0.19384978852694223 0 -0.19384978852982993"/>
      <material name="green"/>
    </visual>
    <collision>
      <geometry>
        <box size="0.5982900000000001 0.05 0.05"/>
      </geometry>
      <origin rpy="0  0.78539816339 0" xyz="0.19384978852694223 0 -0.19384978852982993"/>
    </collision>
    <inertial>
      <mass value="0.5"/>
      <inertia ixx="1.0" ixy="0.0" ixz="0.0" iyy="1.0" iyz="0.0" izz="1.0"/>
    </inertial>
  </link>
  <joint name="base_to_right_rocker" type="fixed">
    <parent link="base_link"/>
    <child link="right_rocker1"/>
    <origin xyz="0 -0.5 0"/>
    <axis rpy="0 0 0" xyz="0 1 0"/>
    
      joint torsional spring plugin 
    <axis>
      <limit>
        <lower>-0.1</lower>
        <upper>0.1</upper>
      </limit>
      <dynamics>
        <spring_stiffness>2500</spring_stiffness>
        <spring_reference>0.06</spring_reference>
        <damping>20.0</damping>
        <friction>0.75</friction>
      </dynamics>
      <use_parent_model_frame>0</use_parent_model_frame>
    </axis>
    <physics>
      <ode>
        <implicit_spring_damper>1</implicit_spring_damper>
        <cfm_damping>1</cfm_damping>
        <limit>
          <cfm>0</cfm>
          <erp>0.2</erp>
        </limit>
      </ode>
    </physics>
  </joint>
  <link name="right_rocker2">
    <visual>
      <geometry>
        <box size="0.323942 0.05 0.05"/>
      </geometry>
      <origin rpy="0  -0.78539816339 0" xyz="-0.09685312292518122 0 -0.096853122926624"/>
      <material name="green"/>
    </visual>
    <collision>
      <geometry>
        <box size="0.323942 0.05 0.05"/>
      </geometry>
      <origin rpy="0  -0.78539816339 0" xyz="-0.09685312292518122 0 -0.096853122926624"/>
    </collision>
    <inertial>
      <mass value="0.5"/>
      <inertia ixx="1.0" ixy="0.0" ixz="0.0" iyy="1.0" iyz="0.0" izz="1.0"/>
    </inertial>
  </link>
  <joint name="right_rocker_joint" type="fixed">
    <parent link="right_rocker1"/>
    <child link="right_rocker2"/>
    <origin xyz="0 0 0"/>
  </joint>
  <link name="right_rocker_bogie1">
    <visual>
      <geometry>
        <box size="0.27394 0.05 0.05"/>
      </geometry>
      <origin rpy="0  0.78539816339 0" xyz="0.09685241581840004 0 -0.0968524158198428"/>
      <material name="green"/>
    </visual>
    <collision>
      <geometry>
        <box size="0.27394 0.05 0.05"/>
      </geometry>
      <origin rpy="0  0.78539816339 0" xyz="0.09685241581840004 0 -0.0968524158198428"/>
      <material name="green"/>
    </collision>
    <inertial>
      <mass value="1"/>
      <inertia ixx="1.0" ixy="0.0" ixz="0.0" iyy="1.0" iyz="0.0" izz="1.0"/>
    </inertial>
  </link>
  <joint name="rocker_to_right_rocker_bogie" type="fixed">
    <parent link="right_rocker2"/>
    <child link="right_rocker_bogie1"/>
    <origin xyz="-0.193706245853248 0 -0.19370624585036245"/>
  </joint>
  <link name="right_rocker_bogie2">
    <visual>
      <geometry>
        <box size="0.27394 0.05 0.05"/>
      </geometry>
      <origin rpy="0  -0.78539816339 0" xyz="-0.09685241581840004 0 -0.0968524158198428"/>
      <material name="green"/>
    </visual>
    <collision>
      <geometry>
        <box size="0.27394 0.05 0.05"/>
      </geometry>
      <origin rpy="0  -0.78539816339 0" xyz="-0.09685241581840004 0 -0.0968524158198428"/>
      <material name="green"/>
    </collision>
    <inertial>
      <mass value="0.5"/>
      <inertia ixx="1.0" ixy="0.0" ixz="0.0" iyy="1.0" iyz="0.0" izz="1.0"/>
    </inertial>
  </link>
  <joint name="right_rocker_bogie_joint" type="fixed">
    <parent link="right_rocker_bogie1"/>
    <child link="right_rocker_bogie2"/>
    <origin xyz="0 0 0"/>
  </joint>
  <link name="right_back_wheel">
    <visual>
      <origin rpy="1.57075 0 0" xyz="0 0 0"/>
      <geometry>
        <cylinder length="0.001" radius="0.127"/>
      </geometry>
      <material name="white"/>
    </visual>
    <collision>
      <origin rpy="1.57075 0 0" xyz="0 0 0"/>
      <geometry>
        <cylinder length="0.001" radius="0.127"/>
      </geometry>
    </collision>
    <inertial>
      <mass value="1"/>
      <inertia ixx="1.0" ixy="0.0" ixz="0.0" iyy="1.0" iyz="0.0" izz="1.0"/>
    </inertial>
  </link>
  <joint name="right_back_wheel_joint" type="continuous">
    <axis rpy="0 0 0" xyz="0 1 0"/>
    <parent link="right_rocker_bogie2"/>
    <child link="right_back_wheel"/>
    <origin rpy="0 0 0" xyz="-0.19370483163680008 0 -0.1937048316396856"/>
  </joint>
  <transmission name="right_back_wheel_trans">
    <type>transmission_interface/SimpleTransmission</type>
    <actuator name="right_back_wheel_motor">
      <mechanicalReduction>1</mechanicalReduction>
    </actuator>
    <joint name="right_back_wheel_joint">
      <!--<hardwareInterface>hardware_interface/EffortJointInterface</hardwareInterface>-->
      <hardwareInterface>hardware_interface/VelocityJointInterface</hardwareInterface>
    </joint>
  </transmission>
  <link name="right_middle_wheel">
    <visual>
      <origin rpy="1.57075 0 0" xyz="0 0 0"/>
      <geometry>
        <cylinder length="0.001" radius="0.127"/>
      </geometry>
      <material name="white"/>
    </visual>
    <collision>
      <origin rpy="1.57075 0 0" xyz="0 0 0"/>
      <geometry>
        <cylinder length="0.001" radius="0.127"/>
      </geometry>
    </collision>
    <inertial>
      <mass value="1"/>
      <inertia ixx="1.0" ixy="0.0" ixz="0.0" iyy="1.0" iyz="0.0" izz="1.0"/>
    </inertial>
  </link>
  <joint name="right_middle_wheel_joint" type="continuous">
    <axis rpy="0 0 0" xyz="0 1 0"/>
    <parent link="right_rocker_bogie1"/>
    <child link="right_middle_wheel"/>
    <origin rpy="0 0 0" xyz="0.19370483163680008 0 -0.1937048316396856"/>
  </joint>
  <transmission name="right_middle_wheel_trans">
    <type>transmission_interface/SimpleTransmission</type>
    <actuator name="right_middle_wheel_motor">
      <mechanicalReduction>1</mechanicalReduction>
    </actuator>
    <joint name="right_middle_wheel_joint">
      <!--<hardwareInterface>hardware_interface/EffortJointInterface</hardwareInterface>-->
      <hardwareInterface>hardware_interface/VelocityJointInterface</hardwareInterface>
    </joint>
  </transmission>
  <link name="right_front_wheel">
    <visual>
      <origin rpy="1.57075 0 0" xyz="0 0 0"/>
      <geometry>
        <cylinder length="0.001" radius="0.127"/>
      </geometry>
      <material name="white"/>
    </visual>
    <collision>
      <origin rpy="1.57075 0 0" xyz="0 0 0"/>
      <geometry>
        <cylinder length="0.001" radius="0.127"/>
      </geometry>
    </collision>
    <inertial>
      <mass value="1"/>
      <inertia ixx="1.0" ixy="0.0" ixz="0.0" iyy="1.0" iyz="0.0" izz="1.0"/>
    </inertial>
  </link>
  <joint name="right_front_wheel_joint" type="continuous">
    <axis rpy="0 0 0" xyz="0 1 0"/>
    <parent link="right_rocker1"/>
    <child link="right_front_wheel"/>
    <origin rpy="0 0 0" xyz="0.38769957705388447 0 -0.38769957705965985"/>
  </joint>
  <transmission name="right_front_wheel_trans">
    <type>transmission_interface/SimpleTransmission</type>
    <actuator name="right_front_wheel_motor">
      <mechanicalReduction>1</mechanicalReduction>
    </actuator>
    <joint name="right_front_wheel_joint">
      <!--<hardwareInterface>hardware_interface/EffortJointInterface</hardwareInterface>-->
      <hardwareInterface>hardware_interface/VelocityJointInterface</hardwareInterface>
    </joint>
  </transmission>
  <link name="left_rocker1">
    <visual>
      <geometry>
        <box size="0.5982900000000001 0.05 0.05"/>
      </geometry>
      <origin rpy="0  0.78539816339 0" xyz="0.19384978852694223 0 -0.19384978852982993"/>
      <material name="green"/>
    </visual>
    <collision>
      <geometry>
        <box size="0.5982900000000001 0.05 0.05"/>
      </geometry>
      <origin rpy="0  0.78539816339 0" xyz="0.19384978852694223 0 -0.19384978852982993"/>
    </collision>
    <inertial>
      <mass value="0.5"/>
      <inertia ixx="1.0" ixy="0.0" ixz="0.0" iyy="1.0" iyz="0.0" izz="1.0"/>
    </inertial>
  </link>
  <joint name="base_to_left_rocker" type="fixed">
    <parent link="base_link"/>
    <child link="left_rocker1"/>
    <origin xyz="0 0.5 0"/>
    <axis rpy="0 0 0" xyz="0 1 0"/>
    
      joint torsional spring plugin 
    <axis>
      <limit>
        <lower>-0.1</lower>
        <upper>0.1</upper>
      </limit>
      <dynamics>
        <spring_stiffness>2500</spring_stiffness>
        <spring_reference>0.06</spring_reference>
        <damping>20.0</damping>
        <friction>0.75</friction>
      </dynamics>
      <use_parent_model_frame>0</use_parent_model_frame>
    </axis>
    <physics>
      <ode>
        <implicit_spring_damper>1</implicit_spring_damper>
        <cfm_damping>1</cfm_damping>
        <limit>
          <cfm>0</cfm>
          <erp>0.2</erp>
        </limit>
      </ode>
    </physics>
  </joint>
  <link name="left_rocker2">
    <visual>
      <geometry>
        <box size="0.323942 0.05 0.05"/>
      </geometry>
      <origin rpy="0  -0.78539816339 0" xyz="-0.09685312292518122 0 -0.096853122926624"/>
      <material name="green"/>
    </visual>
    <collision>
      <geometry>
        <box size="0.323942 0.05 0.05"/>
      </geometry>
      <origin rpy="0  -0.78539816339 0" xyz="-0.09685312292518122 0 -0.096853122926624"/>
    </collision>
    <inertial>
      <mass value="0.5"/>
      <inertia ixx="1.0" ixy="0.0" ixz="0.0" iyy="1.0" iyz="0.0" izz="1.0"/>
    </inertial>
  </link>
  <joint name="left_rocker_joint" type="fixed">
    <parent link="left_rocker1"/>
    <child link="left_rocker2"/>
    <origin xyz="0 0 0"/>
  </joint>
  <link name="left_rocker_bogie1">
    <visual>
      <geometry>
        <box size="0.27394 0.05 0.05"/>
      </geometry>
      <origin rpy="0  0.78539816339 0" xyz="0.09685241581840004 0 -0.0968524158198428"/>
      <material name="green"/>
    </visual>
    <collision>
      <geometry>
        <box size="0.27394 0.05 0.05"/>
      </geometry>
      <origin rpy="0  0.78539816339 0" xyz="0.09685241581840004 0 -0.0968524158198428"/>
      <material name="green"/>
    </collision>
    <inertial>
      <mass value="1"/>
      <inertia ixx="1.0" ixy="0.0" ixz="0.0" iyy="1.0" iyz="0.0" izz="1.0"/>
    </inertial>
  </link>
  <joint name="rocker_to_left_rocker_bogie" type="fixed">
    <parent link="left_rocker2"/>
    <child link="left_rocker_bogie1"/>
    <origin xyz="-0.193706245853248 0 -0.19370624585036245"/>
  </joint>
  <link name="left_rocker_bogie2">
    <visual>
      <geometry>
        <box size="0.27394 0.05 0.05"/>
      </geometry>
      <origin rpy="0  -0.78539816339 0" xyz="-0.09685241581840004 0 -0.0968524158198428"/>
      <material name="green"/>
    </visual>
    <collision>
      <geometry>
        <box size="0.27394 0.05 0.05"/>
      </geometry>
      <origin rpy="0  -0.78539816339 0" xyz="-0.09685241581840004 0 -0.0968524158198428"/>
      <material name="green"/>
    </collision>
    <inertial>
      <mass value="0.5"/>
      <inertia ixx="1.0" ixy="0.0" ixz="0.0" iyy="1.0" iyz="0.0" izz="1.0"/>
    </inertial>
  </link>
  <joint name="left_rocker_bogie_joint" type="fixed">
    <parent link="left_rocker_bogie1"/>
    <child link="left_rocker_bogie2"/>
    <origin xyz="0 0 0"/>
  </joint>
  <link name="left_back_wheel">
    <visual>
      <origin rpy="1.57075 0 0" xyz="0 0 0"/>
      <geometry>
        <cylinder length="0.001" radius="0.127"/>
      </geometry>
      <material name="white"/>
    </visual>
    <collision>
      <origin rpy="1.57075 0 0" xyz="0 0 0"/>
      <geometry>
        <cylinder length="0.001" radius="0.127"/>
      </geometry>
    </collision>
    <inertial>
      <mass value="1"/>
      <inertia ixx="1.0" ixy="0.0" ixz="0.0" iyy="1.0" iyz="0.0" izz="1.0"/>
    </inertial>
  </link>
  <joint name="left_back_wheel_joint" type="continuous">
    <axis rpy="0 0 0" xyz="0 1 0"/>
    <parent link="left_rocker_bogie2"/>
    <child link="left_back_wheel"/>
    <origin rpy="0 0 0" xyz="-0.19370483163680008 0 -0.1937048316396856"/>
  </joint>
  <transmission name="left_back_wheel_trans">
    <type>transmission_interface/SimpleTransmission</type>
    <actuator name="left_back_wheel_motor">
      <mechanicalReduction>1</mechanicalReduction>
    </actuator>
    <joint name="left_back_wheel_joint">
      <!--<hardwareInterface>hardware_interface/EffortJointInterface</hardwareInterface>-->
      <hardwareInterface>hardware_interface/VelocityJointInterface</hardwareInterface>
    </joint>
  </transmission>
  <link name="left_middle_wheel">
    <visual>
      <origin rpy="1.57075 0 0" xyz="0 0 0"/>
      <geometry>
        <cylinder length="0.001" radius="0.127"/>
      </geometry>
      <material name="white"/>
    </visual>
    <collision>
      <origin rpy="1.57075 0 0" xyz="0 0 0"/>
      <geometry>
        <cylinder length="0.001" radius="0.127"/>
      </geometry>
    </collision>
    <inertial>
      <mass value="1"/>
      <inertia ixx="1.0" ixy="0.0" ixz="0.0" iyy="1.0" iyz="0.0" izz="1.0"/>
    </inertial>
  </link>
  <joint name="left_middle_wheel_joint" type="continuous">
    <axis rpy="0 0 0" xyz="0 1 0"/>
    <parent link="left_rocker_bogie1"/>
    <child link="left_middle_wheel"/>
    <origin rpy="0 0 0" xyz="0.19370483163680008 0 -0.1937048316396856"/>
  </joint>
  <transmission name="left_middle_wheel_trans">
    <type>transmission_interface/SimpleTransmission</type>
    <actuator name="left_middle_wheel_motor">
      <mechanicalReduction>1</mechanicalReduction>
    </actuator>
    <joint name="left_middle_wheel_joint">
      <!--<hardwareInterface>hardware_interface/EffortJointInterface</hardwareInterface>-->
      <hardwareInterface>hardware_interface/VelocityJointInterface</hardwareInterface>
    </joint>
  </transmission>
  <link name="left_front_wheel">
    <visual>
      <origin rpy="1.57075 0 0" xyz="0 0 0"/>
      <geometry>
        <cylinder length="0.001" radius="0.127"/>
      </geometry>
      <material name="white"/>
    </visual>
    <collision>
      <origin rpy="1.57075 0 0" xyz="0 0 0"/>
      <geometry>
        <cylinder length="0.001" radius="0.127"/>
      </geometry>
    </collision>
    <inertial>
      <mass value="1"/>
      <inertia ixx="1.0" ixy="0.0" ixz="0.0" iyy="1.0" iyz="0.0" izz="1.0"/>
    </inertial>
  </link>
  <joint name="left_front_wheel_joint" type="continuous">
    <axis rpy="0 0 0" xyz="0 1 0"/>
    <parent link="left_rocker1"/>
    <child link="left_front_wheel"/>
    <origin rpy="0 0 0" xyz="0.38769957705388447 0 -0.38769957705965985"/>
  </joint>
  <transmission name="left_front_wheel_trans">
    <type>transmission_interface/SimpleTransmission</type>
    <actuator name="left_front_wheel_motor">
      <mechanicalReduction>1</mechanicalReduction>
    </actuator>
    <joint name="left_front_wheel_joint">
      <!--<hardwareInterface>hardware_interface/EffortJointInterface</hardwareInterface>-->
      <hardwareInterface>hardware_interface/VelocityJointInterface</hardwareInterface>
    </joint>
  </transmission>
  <gazebo>
    <plugin filename="libgazebo_ros_control.so" name="gazebo_ros_control">
      <robotNamespace>/</robotNamespace>
    </plugin>
  </gazebo>
  <!-- <xacro:include filename="/home/polyorbite/polyorbite/catkin_ws/src/polyorbite_rover/rover_control/bash/fileMaker/suspension_wheels.urdf.xacro"/>-->
  <joint name="camera_base_joint" type="fixed">
    <axis xyz="0 1 0"/>
    <origin rpy="0 0 0" xyz="0.5 0 0"/>
    <parent link="base_link"/>
    <child link="camera_base_link"/>
  </joint>
  <!-- Camera base-->
  <link name="camera_base_link">
    <collision>
      <origin rpy="0 0 0" xyz="0 0 0"/>
      <geometry>
        <box size="0.03 0.175 0.033"/>
      </geometry>
    </collision>
    <visual>
      <origin rpy="0 0 0" xyz="0 0 0"/>
      <geometry>
        <box size="0.03 0.175 0.033"/>
      </geometry>
      <material name="black"/>
    </visual>
    <inertial>
      <mass value="0.166"/>
      <origin rpy="0 0 0" xyz="0 0 0"/>
      <inertia ixx="1e-6" ixy="0" ixz="0" iyy="1e-6" iyz="0" izz="1e-6"/>
    </inertial>
  </link>
  <joint name="camera_right_joint" type="fixed">
    <axis xyz="0 1 0"/>
    <origin rpy="0 0 0" xyz="0.015 -0.08 0"/>
    <parent link="camera_base_link"/>
    <child link="camera_right_link"/>
  </joint>
  <link name="camera_right_link">
    <collision>
      <origin rpy="0 0 0" xyz="0 0 0"/>
      <geometry>
        <box size="0.01 0.01 0.01"/>
      </geometry>
    </collision>
    <visual>
      <origin rpy="0 0 0" xyz="0 0 0"/>
      <geometry>
        <box size="0.01 0.01 0.01"/>
      </geometry>
      <material name="red"/>
    </visual>
    <inertial>
      <mass value="0.166"/>
      <origin rpy="0 0 0" xyz="0 0 0"/>
      <inertia ixx="1e-6" ixy="0" ixz="0" iyy="1e-6" iyz="0" izz="1e-6"/>
    </inertial>
  </link>
  <joint name="camera_left_joint" type="fixed">
    <axis xyz="0 1 0"/>
    <origin rpy="0 0 0" xyz="0.015 0.08 0"/>
    <parent link="camera_base_link"/>
    <child link="camera_left_link"/>
  </joint>
  <link name="camera_left_link">
    <collision>
      <origin rpy="0 0 0" xyz="0 0 0"/>
      <geometry>
        <box size="0.01 0.01 0.01"/>
      </geometry>
    </collision>
    <visual>
      <origin rpy="0 0 0" xyz="0 0 0"/>
      <geometry>
        <box size="0.01 0.01 0.01"/>
      </geometry>
      <material name="red"/>
    </visual>
    <inertial>
      <mass value="0.166"/>
      <origin rpy="0 0 0" xyz="0 0 0"/>
      <inertia ixx="1e-6" ixy="0" ixz="0" iyy="1e-6" iyz="0" izz="1e-6"/>
    </inertial>
  </link>
  <!-- camera -->
  <gazebo reference="camera_left_link">
    <sensor name="stereo_camera" type="multicamera">
      <update_rate>30.0</update_rate>
      <camera name="left">
        <image>
          <width>1280</width>
          <height>720</height>
          <format>R8G8B8</format>
          <hfov>110</hfov>
        </image>
        <clip>
          <near>0.02</near>
          <far>300</far>
        </clip>
        <noise>
          <type>gaussian</type>
          <mean>0.0</mean>
          <stddev>0.007</stddev>
        </noise>
      </camera>
      <camera name="right">
        <pose>0 -0.16 0 0 0 0</pose>
        <image>
          <width>1280</width>
          <height>720</height>
          <hfov>110</hfov>
          <format>R8G8B8</format>
        </image>
        <clip>
          <near>0.02</near>
          <far>300</far>
        </clip>
        <noise>
          <type>gaussian</type>
          <mean>0.0</mean>
          <stddev>0.007</stddev>
        </noise>
      </camera>
      <plugin filename="libgazebo_ros_multicamera.so" name="stereo_camera_controller">
        <alwaysOn>true</alwaysOn>
        <updateRate>0.0</updateRate>
        <cameraName>stereo_camera</cameraName>
        <imageTopicName>image_raw</imageTopicName>
        <cameraInfoTopicName>camera_info</cameraInfoTopicName>
        <frameName>left_cam_rotated</frameName>
        <rightFrameName>right_cam_rotated</rightFrameName>
        <hackBaseline>0.16</hackBaseline>
        <distortionK1>0.0</distortionK1>
        <distortionK2>0.0</distortionK2>
        <distortionK3>0.0</distortionK3>
        <distortionT1>0.0</distortionT1>
        <distortionT2>0.0</distortionT2>
      </plugin>
    </sensor>
    <material>Gazebo/Orange</material>
  </gazebo>
  <gazebo reference="camera_right_link">
    <material>Gazebo/Orange</material>
  </gazebo>
  <gazebo reference="camera_base_link">
    <material>Gazebo/Black</material>
  </gazebo>
  <gazebo>
    <plugin filename="libgazebo_ros_imu.so" name="imu_plugin">
      <alwaysOn>true</alwaysOn>
      <bodyName>camera_left_link</bodyName>
      <topicName>imu/data</topicName>
      <serviceName>imu_service</serviceName>
      <gaussianNoise>0.0</gaussianNoise>
      <updateRate>20.0</updateRate>
    </plugin>
  </gazebo>
  <!-- GPS Tower -->
  <link name="GPS_tower">
    <collision>
      <origin rpy="0 0 0" xyz="0 0 0.20"/>
      <geometry>
        <box size="0.03 0.03 0.3"/>
      </geometry>
    </collision>
    <visual>
      <origin rpy="0 0 0" xyz="0 0 0.20"/>
      <geometry>
        <box size="0.03 0.03 0.3"/>
      </geometry>
      <material name="black"/>
    </visual>
    <inertial>
      <mass value="1"/>
      <inertia ixx="1.0" ixy="0.0" ixz="0.0" iyy="1.0" iyz="0.0" izz="1.0"/>
    </inertial>
  </link>
  <joint name="tower_to_base" type="fixed">
    <parent link="base_link"/>
    <child link="GPS_tower"/>
    <origin xyz="-0.4 -0.4 0"/>
  </joint>
  <!-- GPS Beacon -->
  <link name="GPS_Beacon">
    <collision>
      <origin rpy="0 0 0" xyz="0 0 0"/>
      <geometry>
        <box size="0.07 0.07 0.07"/>
      </geometry>
    </collision>
    <visual>
      <origin rpy="0 0 0" xyz="0 0 0"/>
      <geometry>
        <box size="0.07 0.07 0.07"/>
      </geometry>
      <material name="orange"/>
    </visual>
    <inertial>
      <mass value="1"/>
      <inertia ixx="1.0" ixy="0.0" ixz="0.0" iyy="1.0" iyz="0.0" izz="1.0"/>
    </inertial>
  </link>
  <joint name="beacon_to_tower" type="fixed">
    <parent link="GPS_tower"/>
    <child link="GPS_Beacon"/>
    <origin xyz="0 0 0.35"/>
  </joint>
  <gazebo>
    <plugin filename="libhector_gazebo_ros_gps.so" name="gazebo_ros_gps">
      <updateRate>4.0</updateRate>
      <bodyName>GPS_Beacon</bodyName>
      <frameId>GPS_Beacon</frameId>
      <topicName>/gps/fix</topicName>
      <velocityTopicName>/gps/fix_velocity</velocityTopicName>
      <referenceLatitude>-30.06022459407145675</referenceLatitude>
      <referenceLongitude>-51.173913575780311191</referenceLongitude>
      <referenceHeading>90</referenceHeading>
      <referenceAltitude>10</referenceAltitude>
      <offset>0 0 0</offset>
      <drift>0.001 0.001 0.001</drift>
      <gaussianNoise>0.05 0.05 0.05</gaussianNoise>
      <velocityDrift>0.001 0.001 0.001</velocityDrift>
      <velocityGaussianNoise>0.5 0.5 0.5</velocityGaussianNoise>
      <!--                <drift>0.001 0.001 0.001</drift>-->
      <!--                <gaussianNoise>0.01 0.01 0.01</gaussianNoise>-->
      <!--                <velocityDrift>0 0 0</velocityDrift>-->
      <!--                <velocityGaussianNoise>0.05 0.05 0.05</velocityGaussianNoise>-->
    </plugin>
    <!-- Ground truth plugin -->
    <plugin filename="libgazebo_ros_p3d.so" name="p3d_base_controller">
      <alwaysOn>true</alwaysOn>
      <updateRate>200.0</updateRate>
      <bodyName>base_link</bodyName>
      <topicName>ground_truth/state</topicName>
      <gaussianNoise>0.0</gaussianNoise>
      <frameName>map</frameName>
      <xyzOffsets>0 0 0</xyzOffsets>
      <rpyOffsets>0 0 0</rpyOffsets>
    </plugin>
  </gazebo>
  <gazebo reference="GPS_Beacon">
    <material>Gazebo/Orange</material>
  </gazebo>
</robot>
